Workbook

Sheet Pessoa Física
B2: MESES | C2: 45809 | D2: Meio de Pagamento | E2: 45839 | F2: Meio de Pagamento | G2: 45870 | H2: Meio de Pagamento | I2: 45901 | J2: Meio de Pagamento | K2: 45931 | L2: Meio de Pagamento | M2: 45962 | N2: Meio de Pagamento | O2: 45992 | P2: Meio de Pagamento | Q2: 46023 | R2: Meio de Pagamento | S2: 46054 | T2: Meio de Pagamento | U2: 46082 | V2: Meio de Pagamento | W2: 46113 | X2: Meio de Pagamento | Y2: 46143 | Z2: Meio de Pagamento | AA2: TOTAL
B3: DESPESAS
B4: ALIMENTAÇÃO
B5: Supermercado | C5: 100 | D5: Cartão de Crédito | E5: 90 | F5: Cartão de Crédito | AA5: =SUM(C5,E5,G5,I5,K5,M5,O5,Q5,S5,U5,W5,Y5) -> 190
B6: Feira / Sacolão | C6: 50 | D6: Cartão de Débito | E6: 50 | F6: Cartão de Débito | AA6: =SUM(C6,E6,G6,I6,K6,M6,O6,Q6,S6,U6,W6,Y6) -> 100
B7: Padaria | C7: 30 | D7: Dinheiro | E7: 25 | F7: Dinheiro | AA7: =SUM(C7,E7,G7,I7,K7,M7,O7,Q7,S7,U7,W7,Y7) -> 55
B8: MORADIA
B9: Prestação / Aluguel de imóvel | C9: 100 | D9: Cartão de Crédito | E9: 90 | F9: Cartão de Crédito | AA9: =SUM(C9,E9,G9,I9,K9,M9,O9,Q9,S9,U9,W9,Y9) -> 190
B10: Condomínio | C10: 50 | D10: Cartão de Débito | E10: 50 | F10: Cartão de Débito | AA10: =SUM(C10,E10,G10,I10,K10,M10,O10,Q10,S10,U10,W10,Y10) -> 100
B11: Consumo de água | C11: 30 | D11: Dinheiro | E11: 25 | F11: Dinheiro | AA11: =SUM(C11,E11,G11,I11,K11,M11,O11,Q11,S11,U11,W11,Y11) -> 55
B12: EDUCAÇÃO
B13: Matricula Escolar / Mensalidade | C13: 100 | D13: Cartão de Crédito | E13: 90 | F13: Cartão de Crédito | AA13: =SUM(C13,E13,G13,I13,K13,M13,O13,Q13,S13,U13,W13,Y13) -> 190
B14: Material Escolar | C14: 50 | D14: Cartão de Débito | E14: 50 | F14: Cartão de Débito | AA14: =SUM(C14,E14,G14,I14,K14,M14,O14,Q14,S14,U14,W14,Y14) -> 100
B15: Transporte Escolar | C15: 30 | D15: Dinheiro | E15: 25 | F15: Dinheiro | AA15: =SUM(C15,E15,G15,I15,K15,M15,O15,Q15,S15,U15,W15,Y15) -> 55
B16: ANIMAL DE ESTIMAÇÃO
B17: Ração | C17: 100 | D17: Cartão de Crédito | E17: 90 | F17: Cartão de Crédito | AA17: =SUM(C17,E17,G17,I17,K17,M17,O17,Q17,S17,U17,W17,Y17) -> 190
B18: Banho / Tosa | C18: 50 | D18: Cartão de Débito | E18: 50 | F18: Cartão de Débito | AA18: =SUM(C18,E18,G18,I18,K18,M18,O18,Q18,S18,U18,W18,Y18) -> 100
B19: Veterinário | C19: 30 | D19: Dinheiro | E19: 25 | F19: Dinheiro | AA19: =SUM(C19,E19,G19,I19,K19,M19,O19,Q19,S19,U19,W19,Y19) -> 55
B20: SAÚDE
B21: Plano de Saúde | C21: 100 | D21: Cartão de Crédito | E21: 90 | F21: Cartão de Crédito | AA21: =SUM(C21,E21,G21,I21,K21,M21,O21,Q21,S21,U21,W21,Y21) -> 190
B22: Medicamentos | C22: 50 | D22: Cartão de Débito | E22: 50 | F22: Cartão de Débito | AA22: =SUM(C22,E22,G22,I22,K22,M22,O22,Q22,S22,U22,W22,Y22) -> 100
B23: Dentista | C23: 30 | D23: Dinheiro | E23: 25 | F23: Dinheiro | AA23: =SUM(C23,E23,G23,I23,K23,M23,O23,Q23,S23,U23,W23,Y23) -> 55
B24: TRANSPORTE
B25: Ônibus / Metrô | C25: 100 | D25: Cartão de Crédito | E25: 90 | F25: Cartão de Crédito | AA25: =SUM(C25,E25,G25,I25,K25,M25,O25,Q25,S25,U25,W25,Y25) -> 190
B26: Taxi | C26: 50 | D26: Cartão de Débito | E26: 50 | F26: Cartão de Débito | AA26: =SUM(C26,E26,G26,I26,K26,M26,O26,Q26,S26,U26,W26,Y26) -> 100
B27: Combustível | C27: 30 | D27: Dinheiro | E27: 25 | F27: Dinheiro | AA27: =SUM(C27,E27,G27,I27,K27,M27,O27,Q27,S27,U27,W27,Y27) -> 55
B28: PESSOAL
B29: Vestuário / Calçados / Acessórios | C29: 500 | D29: Cartão de Crédito | E29: 90 | F29: Cartão de Crédito | AA29: =SUM(C29,E29,G29,I29,K29,M29,O29,Q29,S29,U29,W29,Y29) -> 590
B30: Cabeleireiro / Manicure / Higiene Pessoal | C30: 50 | D30: Cartão de Débito | E30: 50 | F30: Cartão de Débito | AA30: =SUM(C30,E30,G30,I30,K30,M30,O30,Q30,S30,U30,W30,Y30) -> 100
B31: Presentes | C31: 30 | D31: Dinheiro | E31: 25 | F31: Dinheiro | AA31: =SUM(C31,E31,G31,I31,K31,M31,O31,Q31,S31,U31,W31,Y31) -> 55
B32: LAZER
B33: Cinema / Teatro / Shows | C33: 100 | D33: Cartão de Crédito | E33: 90 | F33: Cartão de Crédito | AA33: =SUM(C33,E33,G33,I33,K33,M33,O33,Q33,S33,U33,W33,Y33) -> 190
B34: Livros / Revistas | C34: 50 | D34: Cartão de Débito | E34: 50 | F34: Cartão de Débito | AA34: =SUM(C34,E34,G34,I34,K34,M34,O34,Q34,S34,U34,W34,Y34) -> 100
B35: Viagens | C35: 30 | D35: Dinheiro | E35: 25 | F35: Dinheiro | AA35: =SUM(C35,E35,G35,I35,K35,M35,O35,Q35,S35,U35,W35,Y35) -> 55
B36: SERVIÇOS FINANCEIROS
B37: Seguros | C37: 100 | D37: Cartão de Crédito | E37: 90 | F37: Cartão de Crédito | AA37: =SUM(C37,E37,G37,I37,K37,M37,O37,Q37,S37,U37,W37,Y37) -> 190
B38: Investimentos 1 | C38: 50 | D38: Transferência | E38: 50 | F38: Cartão de Débito | AA38: =SUM(C38,E38,G38,I38,K38,M38,O38,Q38,S38,U38,W38,Y38) -> 100
B39: Investimentos 1 | C39: 50 | D39: Transferência | E39: 50 | F39: Cartão de Débito | AA39: =SUM(C39,E39,G39,I39,K39,M39,O39,Q39,S39,U39,W39,Y39) -> 100
B40: Imposto de Renda | C40: 30 | D40: Dinheiro | E40: 25 | F40: Dinheiro
B41: DÍVIDAS
...
